Workbook

Sheet About
A1: BPHEVSP BAU EV Subsidy Percentage | B1: Connecticut | C1: 45051 | F1: State | G1: State
B2: =LOOKUP(B1,F2:G51,G2:G51) -> CT | F2: Alabama | G2: AL
A3: Sources: | B3: Federal Tax Credit Methodology | F3: Alaska | G3: AK
B4: Ernst and Young | F4: Arizona | G4: AZ
B5: 2019 | F5: Arkansas | G5: AR
B6: Federal revenue estimates for potential changes to the plug-in electric drive vehicle tax credit | F6: California | G6: CA
B7: https://www.afpm.org/sites/default/files/issue_resources/EV-Tax-May2019.pdf | F7: Colorado | G7: CO
F8: Connecticut | G8: CT
B9: Historial Sales by Manufacturer | F9: Delaware | G9: DE
B10: Argonne National Laboratory | F10: Florida | G10: FL
B11: 2022 | F11: Georgia | G11: GA
B12: Data provided on request | F12: Hawaii | G12: HI
F13: Idaho | G13: ID
B14: State Rebate Amounts | F14: Illinois | G14: IL
B15: EnergySage | F15: Indiana | G15: IN
B16: 2021 | F16: Iowa | G16: IA
B17: Electric car tax credits and incentives | F17: Kansas | G17: KS
B18: https://www.energysage.com/electric-vehicles/costs-and-benefits-evs/ev-tax-credits/ | F18: Kentucky | G18: KY
F19: Louisiana | G19: LA
B20: Tesla | F20: Maine | G20: ME
B21: 2022 | F21: Maryland | G21: MD
B22: Electric Vehicle & Solar Incentives | F22: Massachusetts | G22: MA
B23: https://www.tesla.com/support/incentives | F23: Michigan | G23: MI
F24: Minnesota | G24: MN
F25: Mississippi | G25: MS
A26: Notes | F26: Missouri | G26: MO
A27: The U.S. only has BAU subsidies for passenger LDVs, not other vehicle types. | F27: Montana | G27: MT
A28: We account for both federal and state-level subsidies for EVs but not for | F28: Nebraska | G28: NE
A29: charging equipment. | F29: Nevada | G29: NV
F30: New Hampshire | G30: NH
A31: For assumptions governing EV tax credit phase-out, see the "Data" tab. | F31: New Jersey | G31: NJ
F32: New Mexico | G32: NM
A33: 2020 to 2012 USD (see cpi.xlsx) | B33: 0.88711067 | F33: New York | G33: NY
F34: North Carolina | G34: NC
F35: North Dakota | G35: ND
F36: Ohio | G36: OH
F37: Oklahoma | G37: OK
F38: Oregon | G38: OR
F39: Pennsylvania | G39: PA
F40: Rhode Island | G40: RI
...

Sheet Summary
A1: Federal EV Subsidy Amount
A2: 2020 | B2: 2021 | C2: 2022 | D2: 2023 | E2: 2024 | F2: 2025 | G2: 2026 | H2: 2027 | I2: 2028 | J2: 2029 | K2: 2030 | L2: 2031 | M2: 2032 | N2: 2033 | O2: 2034 | P2: 2035 | Q2: 2036 | R2: 2037 | S2: 2038 | T2: 2039 | U2: 2040 | V2: 2041 | W2: 2042 | X2: 2043 | Y2: 2044 | Z2: 2045 | AA2: 2046 | AB2: 2047 | AC2: 2048 | AD2: 2049 | AE2: 2050
A3: ='Baseline Calculations'!C104 -> 7491.2019 | B3: ='Baseline Calculations'!D104 -> 7499.3107 | C3: ='Baseline Calculations'!E104 -> 4077.3387 | D3: ='Baseline Calculations'!F104 -> 1603.9285 | E3: ='Baseline Calculations'!G104 -> 945.1635 | F3: ='Baseline Calculations'!H104 -> 474.674 | G3: ='Baseline Calculations'!I104 -> 338.76666 | H3: ='Baseline Calculations'!J104 -> 338.76666 | ... AE3: ='Baseline Calculations'!AG104 -> 0
A5: State EV Subsidy Amounts
A6: This list only includes rebates on the EV itself, not on charging equipment.
A7: It also omits states that do not offer a rebate but do exempt EVs from sales, use, or excise taxes.
A8: State Rebates + Tax Credits Updated 8/11/2021
A9: TC | C9: https://www.energysage.com/electric-vehicles/costs-and-benefits-evs/ev-tax-credits/
A10: Rebates | C10: https://www.tesla.com/support/incentives
A11: Note: Could be an optimistic estimate
A12: State | B12: Population, millions (June 2022) | C12: Category | D12: 2020 | E12: =D12+1 -> 2021 | F12: =E12+1 -> 2022 | G12: =F12+1 -> 2023 | H12: =G12+1 -> 2024 | I12: =H12+1 -> 2025 | J12: =I12+1 -> 2026
A13: CO | B13: 0 | C13: LDV | D13: 2500 | E13: 2500 | F13: 2500 | G13: 2000 | H13: 2000 | I13: 2000 | J13: 2000 | K13: Note: average of cars and truck subsidies, which are different
A14: CT | B14: 0 | C14: LDV | D14: 2250 | E14: 2250 | F14: 2250 | G14: 2250 | H14: 2250 | I14: 2250 | J14: 2250 | R14: https://afdc.energy.gov/laws/11609
A15: DE | B15: 0 | C15: LDV | D15: 1000 | E15: 1000 | F15: 1000 | G15: 1000 | H15: 1000 | I15: 1000 | J15: 1000
A16: NY | B16: 1 | C16: LDV | D16: 500 | E16: 500 | F16: 500 | G16: 500 | H16: 500 | I16: 500 | J16: 500 | K16: Subsidy goes up to 2000 based on battery & price
A17: TX | B17: 0 | C17: LDV | D17: 2500 | E17: 2500 | F17: 2500 | G17: 0 | H17: 0 | I17: 0 | J17: 0 | K17: Note: only 1 year program
A18: CA | B18: 0 | C18: LDV | D18: 1000 | E18: 1000 | F18: 1000 | G18: 1000 | H18: 1000 | I18: 1000 | J18: 1000
A19: LA | B19: 0 | C19: LDV | D19: 1500 | E19: 1500 | F19: 1500 | G19: 1500 | H19: 1500 | I19: 1500 | J19: 1500
A20: ME | B20: 0 | C20: LDV | D20: 2000 | E20: 2000 | F20: 2000 | G20: 2000 | H20: 2000 | I20: 2000 | J20: 2000
A21: MD | B21: 0 | C21: LDV | D21: 0 | E21: 0 | F21: 0 | G21: 0 | H21: 0 | I21: 0 | J21: 0
A22: MA | B22: 0 | C22: LDV | D22: 1500 | E22: 1500 | F22: 1500 | G22: 1500 | H22: 1500 | I22: 1500 | J22: 1500
A23: NJ | B23: 0 | C23: LDV | D23: 4000 | E23: 4000 | F23: 4000 | G23: 4000 | H23: 4000 | I23: 4000 | J23: 4000
A24: OR | B24: 0 | C24: LDV | D24: 1500 | E24: 1500 | F24: 1500 | G24: 1500 | H24: 1500 | I24: 1500 | J24: 1500
A25: VT | B25: 0 | C25: LDV | D25: 3000 | E25: 3000 | F25: 3000 | G25: 3000 | H25: 3000 | I25: 3000 | J25: 3000 | K25: Note: Up to 4000
A26: Rest of country | B26: 0 | D26: 0 | E26: 0 | F26: 0 | G26: 0 | H26: 0 | I26: 0 | J26: 0
A27: USA | B27: 0
A29: Note: Pennsylvania offers a $1750 rebate, but only to the first 250 qualified applicants.
A31: Pop-Weighted State Avg Tax Credit | B31: =About!B2 -> CT
C32: 2020 | D32: 2021 | E32: 2022 | F32: 2023 | G32: 2024 | H32: 2025 | I32: 2026 | J32: 2027 | K32: 2028 | L32: 2029 | M32: 2030 | N32: 2031 | O32: 2032 | P32: 2033 | Q32: 2034 | R32: 2035 | S32: 2036 | T32: 2037 | U32: 2038 | V32: 2039 | W32: 2040 | X32: 2041 | Y32: 2042 | Z32: 2043 | AA32: 2044 | AB32: 2045 | AC32: 2046 | AD32: 2047 | AE32: 2048 | AF32: 2049 | AG32: 2050
C33: =SUMIFS(D$13:D$26,$A$13:$A$26,$B$31) -> 2250 | D33: =SUMIFS(E$13:E$26,$A$13:$A$26,$B$31) -> 2250 | E33: =SUMIFS(F$13:F$26,$A$13:$A$26,$B$31) -> 2250 | F33: =SUMIFS(G$13:G$26,$A$13:$A$26,$B$31) -> 2250 | G33: =SUMIFS(H$13:H$26,$A$13:$A$26,$B$31) -> 2250 | H33: =SUMIFS(I$13:I$26,$A$13:$A$26,$B$31) -> 2250 | I33: =SUMIFS(J$13:J$26,$A$13:$A$26,$B$31) -> 2250 | J33: 0 | K33: =J33 -> 0 | L33: =K33 -> 0 | M33: =L33 -> 0 | N33: =M33 -> 0 | O33: =N33 -> 0 | P33: =O33 -> 0 | Q33: =P33 -> 0 | R33: =Q33 -> 0 | ... AG33: =AF33 -> 0
A34: *without looking at each provision separately, we are not sure whether state programs apply to BEVs only or PHEVs. Therefore, we do not count the state credits in the total below.
A36: Total Tax Credit (2012$)
C37: 2020 | D37: 2021 | E37: 2022 | F37: 2023 | G37: 2024 | H37: 2025 | I37: 2026 | J37: 2027 | K37: 2028 | L37: 2029 | M37: 2030 | N37: 2031 | O37: 2032 | P37: 2033 | Q37: 2034 | R37: 2035 | S37: 2036 | T37: 2037 | U37: 2038 | V37: 2039 | W37: 2040 | X37: 2041 | Y37: 2042 | Z37: 2043 | AA37: 2044 | AB37: 2045 | AC37: 2046 | AD37: 2047 | AE37: 2048 | AF37: 2049 | AG37: 2050
C38: =(A3+C33)*About!$B$33 -> 8641.5242 | D38: =(B3+D33)*About!$B$33 -> 8648.7175 | E38: =(C3+E33)*About!$B$33 -> 5613.0497 | F38: =(D3+F33)*About!$B$33 -> 3418.8611 | G38: =(E3+G33)*About!$B$33 -> 2834.4636 | H38: =(F3+H33)*About!$B$33 -> 2417.0874 | I38: =(G3+I33)*About!$B$33 -> 2296.5225 | J38: =(H3+J33)*About!$B$33 -> 300.52352 | ... AG38: =(AE3+AG33)*About!$B$33 -> 0
A40: Time (Year) | B40: 2020 | C40: 2021 | D40: 2022 | E40: 2023 | F40: 2024 | G40: 2025 | H40: 2026 | I40: 2027 | J40: 2028 | K40: 2029 | L40: 2030 | M40: 2031 | N40: 2032 | O40: 2033 | P40: 2034 | Q40: 2035 | R40: 2036 | S40: 2037 | T40: 2038 | U40: 2039 | V40: 2040 | W40: 2041 | X40: 2042 | Y40: 2043 | Z40: 2044 | AA40: 2045 | AB40: 2046 | AC40: 2047 | AD40: 2048 | AE40: 2049 | AF40: 2050
A41: New Vehicle Price after RnD[LDVs,passenger,plugin hybrid vehicle] : MostRecentRun | B41: 36886 | C41: 37337 | D41: 37329 | E41: 37503 | F41: 37520 | G41: 37634 | H41: 37672 | I41: 37697 | J41: 37738 | K41: 37794 | L41: 37860 | M41: 37933 | N41: 38027 | O41: 38120 | P41: 38168 | Q41: 38205 | R41: 38235 | S41: 38257 | T41: 38267 | U41: 38274 | V41: 38269 | W41: 38269 | X41: 38264 | Y41: 38252 | Z41: 38240 | AA41: 38228 | AB41: 38214 | AC41: 38204 | AD41: 38195 | AE41: 38188 | AF41: 38175
A43: Approximate EV Subsidy Percentage
C44: 2020 | D44: 2021 | E44: 2022 | F44: 2023 | G44: 2024 | H44: 2025 | I44: 2026 | J44: 2027 | K44: 2028 | L44: 2029 | M44: 2030 | N44: 2031 | O44: 2032 | P44: 2033 | Q44: 2034 | R44: 2035 | S44: 2036 | T44: 2037 | U44: 2038 | V44: 2039 | W44: 2040 | X44: 2041 | Y44: 2042 | Z44: 2043 | AA44: 2044 | AB44: 2045 | AC44: 2046 | AD44: 2047 | AE44: 2048 | AF44: 2049 | AG44: 2050
C45: =C38/B41 -> 0.23427653 | D45: =D38/C41 -> 0.23163933 | E45: =E38/D41 -> 0.150367 | F45: =F38/E41 -> 0.091162337 | G45: =G38/F41 -> 0.075545406 | H45: =H38/G41 -> 0.064226162 | I45: =I38/H41 -> 0.060960993 | J45: =J38/I41 -> 0.0079720805 | ... AG45: =AG38/AF41 -> 0

Sheet Baseline Calculations
D1: Projected Cumulative Sales
B2: 2020 | C2: 2021 | D2: 2022 | E2: 2023 | F2: 2024 | G2: 2025 | H2: 2026 | I2: 2027 | J2: 2028 | K2: 2029 | L2: 2030 | M2: 2031 | N2: 2032 | O2: 2033 | P2: 2034 | Q2: 2035 | R2: 2036 | S2: 2037 | T2: 2038 | U2: 2039 | V2: 2040 | W2: 2041 | X2: 2042 | Y2: 2043 | Z2: 2044 | AA2: 2045 | AB2: 2046 | AC2: 2047 | AD2: 2048 | AE2: 2049 | AF2: 2050
A3: Tesla | B3: =SUM('PEV Sales by Manufacturer'!B4:K4) -> 687269 | C3: =SUM('PEV Sales by Manufacturer'!B4:L4) -> 1008187 | D3: =C3+D32+D56 -> 1692769.8 | E3: =D3+E32+E56 -> 2709651.1 | F3: =E3+F32+F56 -> 4128282.4 | G3: =F3+G32+G56 -> 5935399.3 | H3: =G3+H32+H56 -> 8112359.2 | I3: =H3+I32+I56 -> 10669702 | J3: =I3+J32+J56 -> 13625645 | K3: =J3+K32+K56 -> 16961112 | ... AF3: =AE3+AF32+AF56 -> 1.4320855e+08
A4: GM (Cadillac and Chevrolet) | B4: =SUM('PEV Sales by Manufacturer'!B5:K5) -> 246675 | C4: =SUM('PEV Sales by Manufacturer'!B5:L5) -> 271520 | D4: =C4+D33+D57 -> 324534.32 | E4: =D4+E33+E57 -> 403272.41 | F4: =E4+F33+F57 -> 513113.2 | G4: =F4+G33+G57 -> 653026.4 | H4: =G4+H33+H57 -> 821564.8 | I4: =H4+I33+I57 -> 1019539.8 | J4: =I4+J33+J57 -> 1248355.5 | K4: =J4+K33+K57 -> 1506535.3 | ... AF4: =AE4+AF33+AF57 -> 11276322
A5: Nissan | B5: =SUM('PEV Sales by Manufacturer'!B6:K6) -> 151452 | C5: =SUM('PEV Sales by Manufacturer'!B6:L6) -> 165691 | D5: =C5+D34+D58 -> 196065.66 | E5: =D5+E34+E58 -> 241184.27 | F5: =E5+F34+F58 -> 304128.35 | G5: =F5+G34+G58 -> 384309.39 | H5: =G5+H34+H58 -> 480900.2 | I5: =H5+I34+I58 -> 594368.47 | J5: =I5+J34+J58 -> 725522.44 | K5: =J5+K34+K58 -> 873515.73 | ... AF5: =AE5+AF34+AF58 -> 6475062.8
A6: Toyota | B6: =SUM('PEV Sales by Manufacturer'!B7:K7) -> 135451 | C6: =SUM('PEV Sales by Manufacturer'!B7:L7) -> 188218 | D6: =C6+D35+D59 -> 350001.84 | E6: =D6+E35+E59 -> 558850.4 | F6: =E6+F35+F59 -> 833163.63 | G6: =F6+G35+G59 -> 1159507.9 | H6: =G6+H35+H59 -> 1521983.9 | I6: =H6+I35+I59 -> 1906993.9 | J6: =I6+J35+J59 -> 2297314.5 | K6: =J6+K35+K59 -> 2690290.4 | ... AF6: =AE6+AF35+AF59 -> 9911142.8
A7: Ford | B7: =SUM('PEV Sales by Manufacturer'!B8:K8) -> 126312 | C7: =SUM('PEV Sales by Manufacturer'!B8:L8) -> 159546 | D7: =C7+D36+D60 -> 236049.77 | E7: =D7+E36+E60 -> 346103.06 | F7: =E7+F36+F60 -> 497693.64 | G7: =F7+G36+G60 -> 688165.61 | H7: =G7+H36+H60 -> 914125.85 | I7: =H7+I36+I60 -> 1174918.9 | J7: =I7+J36+J60 -> 1470127.2 | K7: =J7+K36+K60 -> 1797830.3 | ... AF7: =AE7+AF36+AF60 -> 13329271
A8: BMW N. America | B8: =SUM('PEV Sales by Manufacturer'!B9:K9) -> 109611 | C8: =SUM('PEV Sales by Manufacturer'!B9:L9) -> 132675 | D8: =C8+D37+D61 -> 200138.5 | E8: =D8+E37+E61 -> 288673.78 | F8: =E8+F37+F61 -> 405862.28 | G8: =F8+G37+G61 -> 546575.44 | H8: =G8+H37+H61 -> 704711.48 | I8: =H8+I37+I61 -> 875339.39 | J8: =I8+J37+J61 -> 1052266.4 | K8: =J8+K37+K61 -> 1234300.1 | ... AF8: =AE8+AF37+AF61 -> 5284551.1
A9: FCA (Chrysler and Fiat) | B9: =SUM('PEV Sales by Manufacturer'!B10:K10) -> 37707 | C9: =SUM('PEV Sales by Manufacturer'!B10:L10) -> 86430 | D9: =C9+D38+D62 -> 235814.92 | E9: =D9+E38+E62 -> 428657.58 | F9: =E9+F38+F62 -> 681947.76 | G9: =F9+G38+G62 -> 983281.38 | H9: =G9+H38+H62 -> 1317977.7 | I9: =H9+I38+I62 -> 1673481 | J9: =I9+J38+J62 -> 2033887.9 | K9: =J9+K38+K62 -> 2396746.6 | ... AF9: =AE9+AF38+AF62 -> 9064201.4
A10: Honda | B10: =SUM('PEV Sales by Manufacturer'!B11:K11) -> 39002 | C10: =SUM('PEV Sales by Manufacturer'!B11:L11) -> 41317 | D10: =C10+D39+D63 -> 48413.867 | E10: =D10+E39+E63 -> 57575.706 | F10: =E10+F39+F63 -> 69609.63 | G10: =F10+G39+G63 -> 83926.49 | H10: =G10+H39+H63 -> 99828.996 | I10: =H10+I39+I63 -> 116720.87 | J10: =I10+J39+J63 -> 133846.88 | K10: =J10+K39+K63 -> 151090.51 | ... AF10: =AE10+AF39+AF63 -> 468141.14
A11: Audi | B11: =SUM('PEV Sales by Manufacturer'!B12:K12) -> 26628 | C11: =SUM('PEV Sales by Manufacturer'!B12:L12) -> 46647 | D11: =C11+D40+D64 -> 97693.617 | E11: =D11+E40+E64 -> 168185.59 | F11: =E11+F40+F64 -> 263638.36 | G11: =F11+G40+G64 -> 381317.4 | H11: =G11+H40+H64 -> 517884.66 | I11: =H11+I40+I64 -> 671399.33 | J11: =I11+J40+J64 -> 839571.13 | K11: =J11+K40+K64 -> 1021291.7 | ... AF11: =AE11+AF40+AF64 -> 6602328.1
A12: Hyundai | B12: =SUM('PEV Sales by Manufacturer'!B13:K13) -> 25223 | C12: =SUM('PEV Sales by Manufacturer'!B13:L13) -> 42236 | D12: =C12+D41+D65 -> 84272.358 | E12: =D12+E41+E65 -> 143041.19 | F12: =E12+F41+F65 -> 223039 | G12: =F12+G41+G65 -> 322249.37 | H12: =G12+H41+H65 -> 438186.28 | I12: =H12+I41+I65 -> 569619.32 | J12: =I12+J41+J65 -> 715154.7 | K12: =J12+K41+K65 -> 873837.3 | ... AF12: =AE12+AF41+AF65 -> 5986822.7
A13: Kia | B13: =SUM('PEV Sales by Manufacturer'!B14:K14) -> 24512 | C13: =SUM('PEV Sales by Manufacturer'!B14:L14) -> 39129 | D13: =C13+D42+D66 -> 75813.544 | E13: =D13+E42+E66 -> 126786.63 | F13: =E13+F42+F66 -> 195992.08 | G13: =F13+G42+G66 -> 281567.56 | H13: =G13+H42+H66 -> 381228.96 | I13: =H13+I42+I66 -> 493742.16 | J13: =I13+J42+J66 -> 617676.2 | K13: =J13+K42+K66 -> 752216.03 | ... AF13: =AE13+AF42+AF66 -> 4988817.8
A14: Volvo | B14: =SUM('PEV Sales by Manufacturer'!B15:K15) -> 19669 | C14: =SUM('PEV Sales by Manufacturer'!B15:L15) -> 45138 | D14: =C14+D43+D67 -> 114025.83 | E14: =D14+E43+E67 -> 207045.96 | F14: =E14+F43+F67 -> 331774.72 | G14: =F14+G43+G67 -> 483831.43 | H14: =G14+H43+H67 -> 657940.87 | I14: =H14+I43+I67 -> 850405.36 | J14: =I14+J43+J67 -> 1056690.9 | K14: =J14+K43+K67 -> 1275426 | ... AF14: =AE14+AF43+AF67 -> 7291066.9
... A24: Mazda | B24: =SUM('PEV Sales by Manufacturer'!B25:K25) -> 0 | C24: =SUM('PEV Sales by Manufacturer'!B25:L25) -> 116 | D24: =C24+D53+D77 -> 363.4514 | E24: =D24+E53+E77 -> 731.01642 | F24: =E24+F53+F77 -> 1243.7992 | G24: =F24+G53+G77 -> 1897.0052 | H24: =G24+H53+H77 -> 2683.8958 | I24: =H24+I53+I77 -> 3608.2808 | J24: =I24+J53+J77 -> 4676.7449 | K24: =J24+K53+K77 -> 5882.3929 | ... AF24: =AE24+AF53+AF77 -> 51516.178
A26: BAU Projected Sales in EPS
A27: Time (Year) | B27: 2020 | C27: 2021 | D27: 2022 | E27: 2023 | F27: 2024 | G27: 2025 | H27: 2026 | I27: 2027 | J27: 2028 | K27: 2029 | L27: 2030 | M27: 2031 | N27: 2032 | O27: 2033 | P27: 2034 | Q27: 2035 | R27: 2036 | S27: 2037 | T27: 2038 | U27: 2039 | V27: 2040 | W27: 2041 | X27: 2042 | Y27: 2043 | Z27: 2044 | AA27: 2045 | AB27: 2046 | AC27: 2047 | AD27: 2048 | AE27: 2049 | AF27: 2050
A28: New Vehicles[LDVs,passenger,battery electric vehicle] : MostRecentRun | B28: 315522 | C28: 533115 | D28: 980091 | E28: 1455830 | F28: 2031000 | G28: 2587180 | H28: 3116670 | I28: 3661250 | J28: 4231910 | K28: 4775260 | L28: 5334220 | M28: 5770560 | N28: 6148760 | O28: 6506160 | P28: 6827330 | Q28: 7142700 | R28: 7433040 | S28: 7732620 | T28: 8042170 | U28: 8326280 | V28: 8622010 | W28: 8924370 | X28: 9210790 | Y28: 9520500 | Z28: 9832410 | AA28: 10127000 | AB28: 10438200 | AC28: 10745100 | AD28: 11040800 | AE28: 11348600 | AF28: 11670000
A29: New Vehicles[LDVs,passenger,plugin hybrid vehicle] : MostRecentRun | B29: 116745 | C29: 360495 | D29: 533730 | E29: 688998 | F29: 904968 | G29: 1076620 | H29: 1195820 | I29: 1270160 | J29: 1287680 | K29: 1296440 | L29: 1287950 | M29: 1283770 | N29: 1261470 | O29: 1233560 | P29: 1206890 | Q29: 1186990 | R29: 1171520 | S29: 1156820 | T29: 1144940 | U29: 1131450 | V29: 1120370 | W29: 1109950 | X29: 1098500 | Y29: 1089190 | Z29: 1079660 | AA29: 1069320 | AB29: 1059440 | AC29: 1049070 | AD29: 1037860 | AE29: 1027010 | AF29: 1016090
A31: Projected Annual BEV Sales by Manufacturer | B31: 2020 | C31: 2021 | D31: 2022 | E31: 2023 | F31: 2024 | G31: 2025 | H31: 2026 | I31: 2027 | J31: 2028 | K31: 2029 | L31: 2030 | M31: 2031 | N31: 2032 | O31: 2033 | P31: 2034 | Q31: 2035 | R31: 2036 | S31: 2037 | T31: 2038 | U31: 2039 | V31: 2040 | W31: 2041 | X31: 2042 | Y31: 2043 | Z31: 2044 | AA31: 2045 | AB31: 2046 | AC31: 2047 | AD31: 2048 | AE31: 2049 | AF31: 2050
A32: Tesla | B32: ='PEV Sales by Manufacturer'!K31 -> 183829 | C32: ='PEV Sales by Manufacturer'!L31 -> 320918 | D32: =D$28*'PEV Sales by Manufacturer'!$Q31 -> 684582.83 | E32: =E$28*'PEV Sales by Manufacturer'!$Q31 -> 1016881.3 | F32: =F$28*'PEV Sales by Manufacturer'!$Q31 -> 1418631.3 | G32: =G$28*'PEV Sales by Manufacturer'!$Q31 -> 1807116.9 | H32: =H$28*'PEV Sales by Manufacturer'!$Q31 -> 2176959.9 | I32: =I$28*'PEV Sales by Manufacturer'!$Q31 -> 2557343 | J32: =J$28*'PEV Sales by Manufacturer'!$Q31 -> 2955942.8 | K32: =K$28*'PEV Sales by Manufacturer'!$Q31 -> 3335466.8 | ... AF32: =AF$28*'PEV Sales by Manufacturer'!$Q31 -> 8151367.2
A33: GM (Cadillac and Chevrolet) | B33: ='PEV Sales by Manufacturer'!K32 -> 20754 | C33: ='PEV Sales by Manufacturer'!L32 -> 24829 | D33: =D$28*'PEV Sales by Manufacturer'!$Q32 -> 52965.266 | E33: =E$28*'PEV Sales by Manufacturer'!$Q32 -> 78674.758 | F33: =F$28*'PEV Sales by Manufacturer'!$Q32 -> 109757.62 | G33: =G$28*'PEV Sales by Manufacturer'!$Q32 -> 139814.24 | H33: =H$28*'PEV Sales by Manufacturer'!$Q32 -> 168428.5 | I33: =I$28*'PEV Sales by Manufacturer'!$Q32 -> 197858.24 | J33: =J$28*'PEV Sales by Manufacturer'!$Q32 -> 228697.37 | K33: =K$28*'PEV Sales by Manufacturer'!$Q32 -> 258060.64 | ... AF33: =AF$28*'PEV Sales by Manufacturer'!$Q32 -> 630660.47
A34: Nissan | B34: ='PEV Sales by Manufacturer'!K33 -> 9564 | C34: ='PEV Sales by Manufacturer'!L33 -> 14239 | D34: =D$28*'PEV Sales by Manufacturer'!$Q33 -> 30374.659 | E34: =E$28*'PEV Sales by Manufacturer'!$Q33 -> 45118.607 | F34: =F$28*'PEV Sales by Manufacturer'!$Q33 -> 62944.087 | G34: =G$28*'PEV Sales by Manufacturer'!$Q33 -> 80181.035 | H34: =H$28*'PEV Sales by Manufacturer'!$Q33 -> 96590.816 | I34: =I$28*'PEV Sales by Manufacturer'!$Q33 -> 113468.26 | J34: =J$28*'PEV Sales by Manufacturer'!$Q33 -> 131153.97 | K34: =K$28*'PEV Sales by Manufacturer'!$Q33 -> 147993.29 | ... AF34: =AF$28*'PEV Sales by Manufacturer'!$Q33 -> 361672.82
A35: Toyota | B35: ='PEV Sales by Manufacturer'!K34 -> 0 | C35: ='PEV Sales by Manufacturer'!L34 -> 0 | D35: =D$28*'PEV Sales by Manufacturer'!$Q34 -> 0 | E35: =E$28*'PEV Sales by Manufacturer'!$Q34 -> 0 | F35: =F$28*'PEV Sales by Manufacturer'!$Q34 -> 0 | G35: =G$28*'PEV Sales by Manufacturer'!$Q34 -> 0 | H35: =H$28*'PEV Sales by Manufacturer'!$Q34 -> 0 | I35: =I$28*'PEV Sales by Manufacturer'!$Q34 -> 0 | J35: =J$28*'PEV Sales by Manufacturer'!$Q34 -> 0 | K35: =K$28*'PEV Sales by Manufacturer'!$Q34 -> 0 | ... AF35: =AF$28*'PEV Sales by Manufacturer'!$Q34 -> 0
A36: Ford | B36: ='PEV Sales by Manufacturer'!K35 -> 3 | C36: ='PEV Sales by Manufacturer'!L35 -> 27221 | D36: =D$28*'PEV Sales by Manufacturer'!$Q35 -> 58067.884 | E36: =E$28*'PEV Sales by Manufacturer'!$Q35 -> 86254.203 | F36: =F$28*'PEV Sales by Manufacturer'!$Q35 -> 120331.55 | G36: =G$28*'PEV Sales by Manufacturer'!$Q35 -> 153283.8 | H36: =H$28*'PEV Sales by Manufacturer'!$Q35 -> 184654.72 | I36: =I$28*'PEV Sales by Manufacturer'!$Q35 -> 216919.7 | J36: =J$28*'PEV Sales by Manufacturer'!$Q35 -> 250729.84 | K36: =K$28*'PEV Sales by Manufacturer'!$Q35 -> 282921.94 | ... AF36: =AF$28*'PEV Sales by Manufacturer'!$Q35 -> 691417.64
A37: BMW N. America | B37: ='PEV Sales by Manufacturer'!K36 -> 2640 | C37: ='PEV Sales by Manufacturer'!L36 -> 3485 | D37: =D$28*'PEV Sales by Manufacturer'!$Q36 -> 7434.208 | E37: =E$28*'PEV Sales by Manufacturer'!$Q36 -> 11042.794 | F37: =F$28*'PEV Sales by Manufacturer'!$Q36 -> 15405.586 | G37: =G$28*'PEV Sales by Manufacturer'!$Q36 -> 19624.335 | H37: =H$28*'PEV Sales by Manufacturer'!$Q36 -> 23640.634 | I37: =I$28*'PEV Sales by Manufacturer'!$Q36 -> 27771.395 | J37: =J$28*'PEV Sales by Manufacturer'!$Q36 -> 32099.978 | K37: =K$28*'PEV Sales by Manufacturer'!$Q36 -> 36221.408 | ... AF37: =AF$28*'PEV Sales by Manufacturer'!$Q36 -> 88519.543
A38: FCA (Chrysler and Fiat) | B38: ='PEV Sales by Manufacturer'!K37 -> 70 | C38: ='PEV Sales by Manufacturer'!L37 -> 0 | D38: =D$28*'PEV Sales by Manufacturer'!$Q37 -> 0 | E38: =E$28*'PEV Sales by Manufacturer'!$Q37 -> 0 | F38: =F$28*'PEV Sales by Manufacturer'!$Q37 -> 0 | G38: =G$28*'PEV Sales by Manufacturer'!$Q37 -> 0 | H38: =H$28*'PEV Sales by Manufacturer'!$Q37 -> 0 | I38: =I$28*'PEV Sales by Manufacturer'!$Q37 -> 0 | J38: =J$28*'PEV Sales by Manufacturer'!$Q37 -> 0 | K38: =K$28*'PEV Sales by Manufacturer'!$Q37 -> 0 | ... AF38: =AF$28*'PEV Sales by Manufacturer'!$Q37 -> 0
A39: Honda | B39: ='PEV Sales by Manufacturer'!K38 -> 45 | C39: ='PEV Sales by Manufacturer'!L38 -> 1 | D39: =D$28*'PEV Sales by Manufacturer'!$Q38 -> 2.1332017 | E39: =E$28*'PEV Sales by Manufacturer'!$Q38 -> 3.168664 | F39: =F$28*'PEV Sales by Manufacturer'!$Q38 -> 4.4205413 | G39: =G$28*'PEV Sales by Manufacturer'!$Q38 -> 5.6310861 | H39: =H$28*'PEV Sales by Manufacturer'!$Q38 -> 6.7835393 | I39: =I$28*'PEV Sales by Manufacturer'!$Q38 -> 7.9688364 | J39: =J$28*'PEV Sales by Manufacturer'!$Q38 -> 9.2108975 | K39: =K$28*'PEV Sales by Manufacturer'!$Q38 -> 10.393517 | ... AF39: =AF$28*'PEV Sales by Manufacturer'!$Q38 -> 25.400156
A40: Audi | B40: ='PEV Sales by Manufacturer'!K39 -> 7202 | C40: ='PEV Sales by Manufacturer'!L39 -> 11076 | D40: =D$28*'PEV Sales by Manufacturer'!$Q39 -> 23627.342 | E40: =E$28*'PEV Sales by Manufacturer'!$Q39 -> 35096.122 | F40: =F$28*'PEV Sales by Manufacturer'!$Q39 -> 48961.915 | G40: =G$28*'PEV Sales by Manufacturer'!$Q39 -> 62369.91 | H40: =H$28*'PEV Sales by Manufacturer'!$Q39 -> 75134.481 | I40: =I$28*'PEV Sales by Manufacturer'!$Q39 -> 88262.832 | J40: =J$28*'PEV Sales by Manufacturer'!$Q39 -> 102019.9 | K40: =K$28*'PEV Sales by Manufacturer'!$Q39 -> 115118.6 | ... AF40: =AF$28*'PEV Sales by Manufacturer'!$Q39 -> 281332.13
A41: Hyundai | B41: ='PEV Sales by Manufacturer'!K40 -> 4556 | C41: ='PEV Sales by Manufacturer'!L40 -> 10855 | D41: =D$28*'PEV Sales by Manufacturer'!$Q40 -> 23155.905 | E41: =E$28*'PEV Sales by Manufacturer'!$Q40 -> 34395.848 | F41: =F$28*'PEV Sales by Manufacturer'!$Q40 -> 47984.975 | G41: =G$28*'PEV Sales by Manufacturer'!$Q40 -> 61125.44 | H41: =H$28*'PEV Sales by Manufacturer'!$Q40 -> 73635.319 | I41: =I$28*'PEV Sales by Manufacturer'!$Q40 -> 86501.719 | J41: =J$28*'PEV Sales by Manufacturer'!$Q40 -> 99984.292 | K41: =K$28*'PEV Sales by Manufacturer'!$Q40 -> 112821.63 | ... AF41: =AF$28*'PEV Sales by Manufacturer'!$Q40 -> 275718.69
A42: Kia | B42: ='PEV Sales by Manufacturer'!K41 -> 2848 | C42: ='PEV Sales by Manufacturer'!L41 -> 8717 | D42: =D$28*'PEV Sales by Manufacturer'!$Q41 -> 18595.119 | E42: =E$28*'PEV Sales by Manufacturer'!$Q41 -> 27621.244 | F42: =F$28*'PEV Sales by Manufacturer'!$Q41 -> 38533.858 | G42: =G$28*'PEV Sales by Manufacturer'!$Q41 -> 49086.178 | H42: =H$28*'PEV Sales by Manufacturer'!$Q41 -> 59132.112 | I42: =I$28*'PEV Sales by Manufacturer'!$Q41 -> 69464.347 | J42: =J$28*'PEV Sales by Manufacturer'!$Q41 -> 80291.393 | K42: =K$28*'PEV Sales by Manufacturer'!$Q41 -> 90600.291 | ... AF42: =AF$28*'PEV Sales by Manufacturer'!$Q41 -> 221413.16
A43: Volvo | B43: ='PEV Sales by Manufacturer'!K42 -> 135 | C43: ='PEV Sales by Manufacturer'!L42 -> 9863 | D43: =D$28*'PEV Sales by Manufacturer'!$Q42 -> 21039.769 | E43: =E$28*'PEV Sales by Manufacturer'!$Q42 -> 31252.533 | F43: =F$28*'PEV Sales by Manufacturer'!$Q42 -> 43599.798 | G43: =G$28*'PEV Sales by Manufacturer'!$Q42 -> 55539.403 | H43: =H$28*'PEV Sales by Manufacturer'!$Q42 -> 66906.048 | I43: =I$28*'PEV Sales by Manufacturer'!$Q42 -> 78596.633 | J43: =J$28*'PEV Sales by Manufacturer'!$Q42 -> 90847.082 | K43: =K$28*'PEV Sales by Manufacturer'!$Q42 -> 102511.26 | ... AF43: =AF$28*'PEV Sales by Manufacturer'!$Q42 -> 250521.74
... A53: Mazda | B53: ='PEV Sales by Manufacturer'!K52 -> 0 | C53: ='PEV Sales by Manufacturer'!L52 -> 116 | D53: =D$28*'PEV Sales by Manufacturer'!$Q52 -> 247.4514 | E53: =E$28*'PEV Sales by Manufacturer'!$Q52 -> 367.56502 | F53: =F$28*'PEV Sales by Manufacturer'!$Q52 -> 512.78279 | G53: =G$28*'PEV Sales by Manufacturer'!$Q52 -> 653.20599 | H53: =H$28*'PEV Sales by Manufacturer'!$Q52 -> 786.89056 | I53: =I$28*'PEV Sales by Manufacturer'!$Q52 -> 924.38502 | J53: =J$28*'PEV Sales by Manufacturer'!$Q52 -> 1068.4641 | K53: =K$28*'PEV Sales by Manufacturer'!$Q52 -> 1205.648 | ... AF53: =AF$28*'PEV Sales by Manufacturer'!$Q52 -> 2946.4181
A55: Projected Annual PHEV Sales by Manufacturer | B55: 2020 | C55: 2021 | D55: 2022 | E55: 2023 | F55: 2024 | G55: 2025 | H55: 2026 | I55: 2027 | J55: 2028 | K55: 2029 | L55: 2030 | M55: 2031 | N55: 2032 | O55: 2033 | P55: 2034 | Q55: 2035 | R55: 2036 | S55: 2037 | T55: 2038 | U55: 2039 | V55: 2040 | W55: 2041 | X55: 2042 | Y55: 2043 | Z55: 2044 | AA55: 2045 | AB55: 2046 | AC55: 2047 | AD55: 2048 | AE55: 2049 | AF55: 2050
A56: Tesla | B56: ='PEV Sales by Manufacturer'!K58 -> 0 | C56: ='PEV Sales by Manufacturer'!L58 -> 0 | D56: =D$29*'PEV Sales by Manufacturer'!$Q58 -> 0 | E56: =E$29*'PEV Sales by Manufacturer'!$Q58 -> 0 | F56: =F$29*'PEV Sales by Manufacturer'!$Q58 -> 0 | G56: =G$29*'PEV Sales by Manufacturer'!$Q58 -> 0 | H56: =H$29*'PEV Sales by Manufacturer'!$Q58 -> 0 | I56: =I$29*'PEV Sales by Manufacturer'!$Q58 -> 0 | J56: =J$29*'PEV Sales by Manufacturer'!$Q58 -> 0 | K56: =K$29*'PEV Sales by Manufacturer'!$Q58 -> 0 | ... AF56: =AF$29*'PEV Sales by Manufacturer'!$Q58 -> 0
A57: GM (Cadillac and Chevrolet) | B57: ='PEV Sales by Manufacturer'!K59 -> 81 | C57: ='PEV Sales by Manufacturer'!L59 -> 16 | D57: =D$29*'PEV Sales by Manufacturer'!$Q59 -> 49.056066 | E57: =E$29*'PEV Sales by Manufacturer'!$Q59 -> 63.327022 | F57: =F$29*'PEV Sales by Manufacturer'!$Q59 -> 83.177206 | G57: =G$29*'PEV Sales by Manufacturer'!$Q59 -> 98.954044 | H57: =H$29*'PEV Sales by Manufacturer'!$Q59 -> 109.90993 | I57: =I$29*'PEV Sales by Manufacturer'!$Q59 -> 116.74265 | J57: =J$29*'PEV Sales by Manufacturer'!$Q59 -> 118.35294 | K57: =K$29*'PEV Sales by Manufacturer'!$Q59 -> 119.15809 | ... AF57: =AF$29*'PEV Sales by Manufacturer'!$Q59 -> 93.390625
A58: Nissan | B58: ='PEV Sales by Manufacturer'!K60 -> 0 | C58: ='PEV Sales by Manufacturer'!L60 -> 0 | D58: =D$29*'PEV Sales by Manufacturer'!$Q60 -> 0 | E58: =E$29*'PEV Sales by Manufacturer'!$Q60 -> 0 | F58: =F$29*'PEV Sales by Manufacturer'!$Q60 -> 0 | G58: =G$29*'PEV Sales by Manufacturer'!$Q60 -> 0 | H58: =H$29*'PEV Sales by Manufacturer'!$Q60 -> 0 | I58: =I$29*'PEV Sales by Manufacturer'!$Q60 -> 0 | J58: =J$29*'PEV Sales by Manufacturer'!$Q60 -> 0 | K58: =K$29*'PEV Sales by Manufacturer'!$Q60 -> 0 | ... AF58: =AF$29*'PEV Sales by Manufacturer'!$Q60 -> 0
A59: Toyota | B59: ='PEV Sales by Manufacturer'!K61 -> 17898 | C59: ='PEV Sales by Manufacturer'!L61 -> 52767 | D59: =D$29*'PEV Sales by Manufacturer'!$Q61 -> 161783.84 | E59: =E$29*'PEV Sales by Manufacturer'!$Q61 -> 208848.56 | F59: =F$29*'PEV Sales by Manufacturer'!$Q61 -> 274313.23 | G59: =G$29*'PEV Sales by Manufacturer'!$Q61 -> 326344.25 | H59: =H$29*'PEV Sales by Manufacturer'!$Q61 -> 362476.07 | I59: =I$29*'PEV Sales by Manufacturer'!$Q61 -> 385009.95 | J59: =J$29*'PEV Sales by Manufacturer'!$Q61 -> 390320.6 | K59: =K$29*'PEV Sales by Manufacturer'!$Q61 -> 392975.93 | ... AF59: =AF$29*'PEV Sales by Manufacturer'!$Q61 -> 307996.44
A60: Ford | B60: ='PEV Sales by Manufacturer'!K62 -> 5565 | C60: ='PEV Sales by Manufacturer'!L62 -> 6013 | D60: =D$29*'PEV Sales by Manufacturer'!$Q62 -> 18435.883 | E60: =E$29*'PEV Sales by Manufacturer'!$Q62 -> 23799.086 | F60: =F$29*'PEV Sales by Manufacturer'!$Q62 -> 31259.034 | G60: =G$29*'PEV Sales by Manufacturer'!$Q62 -> 37188.167 | H60: =H$29*'PEV Sales by Manufacturer'!$Q62 -> 41305.524 | I60: =I$29*'PEV Sales by Manufacturer'!$Q62 -> 43873.346 | J60: =J$29*'PEV Sales by Manufacturer'!$Q62 -> 44478.515 | K60: =K$29*'PEV Sales by Manufacturer'!$Q62 -> 44781.099 | ... AF60: =AF$29*'PEV Sales by Manufacturer'!$Q62 -> 35097.364
A61: BMW N. America | B61: ='PEV Sales by Manufacturer'!K63 -> 7999 | C61: ='PEV Sales by Manufacturer'!L63 -> 19579 | D61: =D$29*'PEV Sales by Manufacturer'!$Q63 -> 60029.295 | E61: =E$29*'PEV Sales by Manufacturer'!$Q63 -> 77492.485 | F61: =F$29*'PEV Sales by Manufacturer'!$Q63 -> 101782.91 | G61: =G$29*'PEV Sales by Manufacturer'!$Q63 -> 121088.83 | H61: =H$29*'PEV Sales by Manufacturer'!$Q63 -> 134495.4 | I61: =I$29*'PEV Sales by Manufacturer'!$Q63 -> 142856.52 | J61: =J$29*'PEV Sales by Manufacturer'!$Q63 -> 144827.01 | K61: =K$29*'PEV Sales by Manufacturer'!$Q63 -> 145812.26 | ... AF61: =AF$29*'PEV Sales by Manufacturer'!$Q63 -> 114280.94
...

Sheet PEV Sales by Manufacturer
A1: Data summarized by Argonne National Laboratory, 6/22/2022, contact yzhou@anl.gov
A2: PEV
A3: Manufacturer | B3: 2011 | C3: 2012 | D3: 2013 | E3: 2014 | F3: 2015 | G3: 2016 | H3: 2017 | I3: 2018 | J3: 2019 | K3: 2020 | L3: 2021 | M3: 2022* | O3: Total | P3: Percentage of Total, 2021
A4: Tesla | C4: 2400 | D4: 19400 | E4: 16750 | F4: 26408 | G4: 49800 | H4: 49970 | I4: 161123 | J4: 177589 | K4: 183829 | L4: 320918 | M4: 180520 | O4: 1188707 | P4: =L4/$L$27 -> 0.50655853
A5: GM (Cadillac and Chevrolet) | B5: 7671 | C5: 23461 | D5: 23660 | E5: 21260 | F5: 19046 | G5: 28887 | H5: 43891 | I5: 36594 | J5: 21370 | K5: 20835 | L5: 24845 | M5: 3680 | O5: 275200 | P5: =L5/$L$27 -> 0.039217017
A6: Nissan | B6: 9674 | C6: 9819 | D6: 22610 | E6: 30200 | F6: 17269 | G6: 14006 | H6: 11230 | I6: 14715 | J6: 12365 | K6: 9564 | L6: 14239 | M6: 7037 | O6: 172728 | P6: =L6/$L$27 -> 0.022475794
A7: Toyota | C7: 12941 | D7: 13093 | E7: 14448 | F7: 4209 | G7: 2474 | H7: 20936 | I7: 27596 | J7: 21856 | K7: 17898 | L7: 52767 | M7: 13578 | O7: 201796 | P7: =L7/$L$27 -> 0.083290978
A8: Ford | C8: 3057 | D8: 14981 | E8: 21947 | F8: 18923 | G8: 24796 | H8: 19589 | I8: 9216 | J8: 8235 | K8: 5568 | L8: 33234 | M8: 23819 | O8: 183365 | P8: =L8/$L$27 -> 0.052458778
A9: BMW N. America | C9: 673 | D9: 0 | E9: 6647 | F9: 14181 | G9: 16117 | H9: 21195 | I9: 26092 | J9: 14067 | K9: 10639 | L9: 23064 | M9: 7611 | O9: 140286 | P9: =L9/$L$27 -> 0.036405767
A10: FCA (Chrysler and Fiat) | D10: 260 | E10: 1503 | F10: 3477 | G10: 3737 | H10: 6317 | I10: 9897 | J10: 6850 | K10: 5666 | L10: 48723 | M10: 30098 | O10: 116528 | P10: =L10/$L$27 -> 0.076907657
A11: Honda | C11: 93 | D11: 1095 | E11: 856 | F11: 66 | G11: 0 | H11: 2024 | I11: 19550 | J11: 11334 | K11: 3984 | L11: 2315 | M11: 2 | O11: 41319 | P11: =L11/$L$27 -> 0.0036541515
A12: Audi | G12: 4280 | H12: 2877 | I12: 2391 | J12: 5410 | K12: 11670 | L12: 20019 | M12: 9704 | O12: 56351 | P12: =L12/$L$27 -> 0.031599335
A13: Hyundai | F13: 15 | G13: 3000 | H13: 2686 | I13: 2684 | J13: 8045 | K13: 8793 | L13: 17013 | M13: 17215 | O13: 59451 | P13: =L13/$L$27 -> 0.026854462
A14: Kia | E14: 359 | F14: 1015 | G14: 1728 | H14: 3669 | I14: 5670 | J14: 6769 | K14: 5302 | L14: 14617 | M14: 19481 | O14: 58610 | P14: =L14/$L$27 -> 0.023072455
A15: Volvo | F15: 86 | G15: 2015 | H15: 2826 | I15: 3818 | J15: 3683 | K15: 7241 | L15: 25469 | M15: 13813 | O15: 58951 | P15: =L15/$L$27 -> 0.040201981
A16: Porsche | D16: 51 | E16: 991 | F16: 1570 | G16: 2504 | H16: 1592 | I16: 2152 | J16: 2705 | K16: 6935 | L16: 11931 | M16: 4760 | O16: 35191 | P16: =L16/$L$27 -> 0.018832692
A17: Volkswagon | E17: 357 | F17: 4232 | G17: 3937 | H17: 3534 | I17: 1354 | J17: 4863 | K17: 767 | L17: 16775 | M17: 3820 | O17: 39639 | P17: =L17/$L$27 -> 0.026478787
A18: Merdeces-Benz | E18: 774 | F18: 2024 | G18: 1584 | H18: 2690 | I18: 2336 | J18: 5389 | K18: 1236 | L18: 507 | M18: 3280 | O18: 19820 | P18: =L18/$L$27 -> 0.00080028286
A19: Mitsubishi | B19: 76 | C19: 588 | D19: 1029 | E19: 196 | F19: 115 | G19: 94 | H19: 105 | I19: 4166 | J19: 2810 | K19: 1964 | L19: 2250 | M19: 1158 | O19: 14551 | P19: =L19/$L$27 -> 0.0035515512
A20: Smart USA | B20: 342 | C20: 139 | D20: 923 | E20: 2594 | F20: 1387 | G20: 657 | H20: 544 | I20: 1198 | J20: 680 | K20: 0 | L20: 0 | M20: 0 | O20: 8464 | P20: =L20/$L$27 -> 0
A21: Jaguar Land Rover | I21: 393 | J21: 3002 | K21: 3129 | L21: 1665 | M21: 251 | O21: 8440 | P21: =L21/$L$27 -> 0.0026281479
A22: Subaru | I22: 0 | J22: 2591 | K22: 2514 | L22: 2618 | M22: 947 | O22: 8670 | P22: =L22/$L$27 -> 0.0041324271
A23: Rivian | L23: 376 | M23: 3551 | O23: 3927 | P23: =L23/$L$27 -> 0.00059350366
A24: Lucid | L24: 65 | M24: 600 | O24: 665 | P24: =L24/$L$27 -> 0.00010260037
A25: Mazda | L25: 116 | M25: 293 | O25: 409 | P25: =L25/$L$27 -> 0.00018310219
A27: Total | B27: 17763 | C27: 53171 | D27: 97102 | E27: 118882 | F27: 114023 | G27: 159616 | H27: 195675 | I27: 330945 | J27: 319613 | K27: 307534 | L27: 633526 | M27: 345218 | O27: 2693068
A29: BEV Only
A30: Manufacturer | B30: 2011 | C30: 2012 | D30: 2013 | E30: 2014 | F30: 2015 | G30: 2016 | H30: 2017 | I30: 2018 | J30: 2019 | K30: 2020 | L30: 2021 | M30: 2022* | O30: Total | Q30: Percentage of 2021 Sales
A31: Tesla | C31: 2400 | D31: 19400 | E31: 16750 | F31: 26408 | G31: 49800 | H31: 49970 | I31: 161123 | J31: 177589 | K31: 183829 | L31: 320918 | M31: 180520 | O31: =SUM(B31:M31) -> 1188707 | Q31: =L31/$L$54 -> 0.69848905
A32: GM (Cadillac and Chevrolet) | B32: 0 | C32: 0 | D32: 560 | E32: 1145 | F32: 2629 | G32: 3614 | H32: 23320 | I32: 18026 | J32: 16418 | K32: 20754 | L32: 24829 | M32: 3680 | O32: =SUM(B32:M32) -> 114975 | Q32: =L32/$L$54 -> 0.054041171
A33: Nissan | B33: 9674 | C33: 9819 | D33: 22610 | E33: 30200 | F33: 17269 | G33: 14006 | H33: 11230 | I33: 14715 | J33: 12365 | K33: 9564 | L33: 14239 | M33: 7037 | O33: =SUM(B33:M33) -> 172728 | Q33: =L33/$L$54 -> 0.030991673
A34: Toyota | C34: 192 | D34: 1005 | E34: 1184 | F34: 18 | G34: 0 | H34: 0 | I34: 1 | J34: 0 | K34: 0 | L34: 0 | M34: 199 | O34: =SUM(B34:M34) -> 2599 | Q34: =L34/$L$54 -> 0
A35: Ford | C35: 683 | D35: 1738 | E35: 1964 | F35: 1582 | G35: 901 | H35: 1817 | I35: 560 | J35: 0 | K35: 3 | L35: 27221 | M35: 18763 | O35: =SUM(B35:M35) -> 55232 | Q35: =L35/$L$54 -> 0.059247441
A36: BMW N. America | C36: 673 | D36: 0 | E36: 6092 | F36: 11024 | G36: 7625 | H36: 6276 | I36: 6117 | J36: 4854 | K36: 2640 | L36: 3485 | M36: 2392 | O36: =SUM(B36:M36) -> 51178 | Q36: =L36/$L$54 -> 0.0075852222
A37: FCA (Chrysler and Fiat) | D37: 260 | E37: 1503 | F37: 3477 | G37: 3737 | H37: 3336 | I37: 1022 | J37: 604 | K37: 70 | L37: 0 | M37: 0 | O37: =SUM(B37:M37) -> 14009 | Q37: =L37/$L$54 -> 0
A38: Honda | C38: 93 | D38: 569 | E38: 407 | F38: 2 | G38: 0 | H38: 1121 | I38: 948 | J38: 576 | K38: 45 | L38: 1 | M38: 0 | O38: =SUM(B38:M38) -> 3762 | Q38: =L38/$L$54 -> 2.1765343e-06
A39: Audi | G39: 0 | H39: 0 | I39: 0 | J39: 5369 | K39: 7202 | L39: 11076 | M39: 5530 | O39: =SUM(B39:M39) -> 29177 | Q39: =L39/$L$54 -> 0.024107294
A40: Hyundai | F40: 0 | G40: 0 | H40: 432 | I40: 474 | J40: 5244 | K40: 4556 | L40: 10855 | M40: 13030 | O40: =SUM(B40:M40) -> 34591 | Q40: =L40/$L$54 -> 0.02362628
A41: Kia | E41: 359 | F41: 1015 | G41: 1728 | H41: 2157 | I41: 996 | J41: 2528 | K41: 2848 | L41: 8717 | M41: 15261 | O41: =SUM(B41:M41) -> 35609 | Q41: =L41/$L$54 -> 0.01897285
A42: Volvo | F42: 0 | G42: 0 | H42: 0 | I42: 0 | J42: 0 | K42: 135 | L42: 9863 | M42: 7331 | O42: =SUM(B42:M42) -> 17329 | Q42: =L42/$L$54 -> 0.021467158
...

Sheet BPHEVSP-passengers
A1: Subsidy Percentage (dimensionless) | B1: 2020 | C1: 2021 | D1: 2022 | E1: 2023 | F1: 2024 | G1: 2025 | H1: 2026 | I1: 2027 | J1: 2028 | K1: 2029 | L1: 2030 | M1: 2031 | N1: 2032 | O1: 2033 | P1: 2034 | Q1: 2035 | R1: 2036 | S1: 2037 | T1: 2038 | U1: 2039 | V1: 2040 | W1: 2041 | X1: 2042 | Y1: 2043 | Z1: 2044 | AA1: 2045 | AB1: 2046 | AC1: 2047 | AD1: 2048 | AE1: 2049 | AF1: 2050
A2: LDVs | B2: =Summary!C38 -> 8641.5242 | C2: =Summary!D38 -> 8648.7175 | D2: =Summary!E38 -> 5613.0497 | E2: =Summary!F38 -> 3418.8611 | F2: =Summary!G38 -> 2834.4636 | G2: =Summary!H38 -> 2417.0874 | H2: =Summary!I38 -> 2296.5225 | I2: =Summary!J38 -> 300.52352 | ... AF2: =Summary!AG38 -> 0
A3: HDVs | B3: 0 | C3: 0 | D3: 0 | E3: 0 | F3: 0 | G3: 0 | H3: 0 | I3: 0 | J3: 0 | K3: 0 | L3: 0 | M3: 0 | N3: 0 | O3: 0 | P3: 0 | Q3: 0 | R3: 0 | S3: 0 | T3: 0 | U3: 0 | V3: 0 | W3: 0 | X3: 0 | Y3: 0 | Z3: 0 | AA3: 0 | AB3: 0 | AC3: 0 | AD3: 0 | AE3: 0 | AF3: 0
A4: aircraft | B4: 0 | C4: 0 | D4: 0 | E4: 0 | F4: 0 | G4: 0 | H4: 0 | I4: 0 | J4: 0 | K4: 0 | L4: 0 | M4: 0 | N4: 0 | O4: 0 | P4: 0 | Q4: 0 | R4: 0 | S4: 0 | T4: 0 | U4: 0 | V4: 0 | W4: 0 | X4: 0 | Y4: 0 | Z4: 0 | AA4: 0 | AB4: 0 | AC4: 0 | AD4: 0 | AE4: 0 | AF4: 0
A5: rail | B5: 0 | C5: 0 | D5: 0 | E5: 0 | F5: 0 | G5: 0 | H5: 0 | I5: 0 | J5: 0 | K5: 0 | L5: 0 | M5: 0 | N5: 0 | O5: 0 | P5: 0 | Q5: 0 | R5: 0 | S5: 0 | T5: 0 | U5: 0 | V5: 0 | W5: 0 | X5: 0 | Y5: 0 | Z5: 0 | AA5: 0 | AB5: 0 | AC5: 0 | AD5: 0 | AE5: 0 | AF5: 0
A6: ships | B6: 0 | C6: 0 | D6: 0 | E6: 0 | F6: 0 | G6: 0 | H6: 0 | I6: 0 | J6: 0 | K6: 0 | L6: 0 | M6: 0 | N6: 0 | O6: 0 | P6: 0 | Q6: 0 | R6: 0 | S6: 0 | T6: 0 | U6: 0 | V6: 0 | W6: 0 | X6: 0 | Y6: 0 | Z6: 0 | AA6: 0 | AB6: 0 | AC6: 0 | AD6: 0 | AE6: 0 | AF6: 0
A7: motorbikes | B7: 0 | C7: 0 | D7: 0 | E7: 0 | F7: 0 | G7: 0 | H7: 0 | I7: 0 | J7: 0 | K7: 0 | L7: 0 | M7: 0 | N7: 0 | O7: 0 | P7: 0 | Q7: 0 | R7: 0 | S7: 0 | T7: 0 | U7: 0 | V7: 0 | W7: 0 | X7: 0 | Y7: 0 | Z7: 0 | AA7: 0 | AB7: 0 | AC7: 0 | AD7: 0 | AE7: 0 | AF7: 0

Sheet BPHEVSP-freight
A1: Subsidy Percentage (dimensionless) | B1: 2020 | C1: 2021 | D1: 2022 | E1: 2023 | F1: 2024 | G1: 2025 | H1: 2026 | I1: 2027 | J1: 2028 | K1: 2029 | L1: 2030 | M1: 2031 | N1: 2032 | O1: 2033 | P1: 2034 | Q1: 2035 | R1: 2036 | S1: 2037 | T1: 2038 | U1: 2039 | V1: 2040 | W1: 2041 | X1: 2042 | Y1: 2043 | Z1: 2044 | AA1: 2045 | AB1: 2046 | AC1: 2047 | AD1: 2048 | AE1: 2049 | AF1: 2050
A2: LDVs | B2: 0 | C2: 0 | D2: 0 | E2: 0 | F2: 0 | G2: 0 | H2: 0 | I2: 0 | J2: 0 | K2: 0 | L2: 0 | M2: 0 | N2: 0 | O2: 0 | P2: 0 | Q2: 0 | R2: 0 | S2: 0 | T2: 0 | U2: 0 | V2: 0 | W2: 0 | X2: 0 | Y2: 0 | Z2: 0 | AA2: 0 | AB2: 0 | AC2: 0 | AD2: 0 | AE2: 0 | AF2: 0
A3: HDVs | B3: 0 | C3: 0 | D3: 0 | E3: 0 | F3: 0 | G3: 0 | H3: 0 | I3: 0 | J3: 0 | K3: 0 | L3: 0 | M3: 0 | N3: 0 | O3: 0 | P3: 0 | Q3: 0 | R3: 0 | S3: 0 | T3: 0 | U3: 0 | V3: 0 | W3: 0 | X3: 0 | Y3: 0 | Z3: 0 | AA3: 0 | AB3: 0 | AC3: 0 | AD3: 0 | AE3: 0 | AF3: 0
A4: aircraft | B4: 0 | C4: 0 | D4: 0 | E4: 0 | F4: 0 | G4: 0 | H4: 0 | I4: 0 | J4: 0 | K4: 0 | L4: 0 | M4: 0 | N4: 0 | O4: 0 | P4: 0 | Q4: 0 | R4: 0 | S4: 0 | T4: 0 | U4: 0 | V4: 0 | W4: 0 | X4: 0 | Y4: 0 | Z4: 0 | AA4: 0 | AB4: 0 | AC4: 0 | AD4: 0 | AE4: 0 | AF4: 0
A5: rail | B5: 0 | C5: 0 | D5: 0 | E5: 0 | F5: 0 | G5: 0 | H5: 0 | I5: 0 | J5: 0 | K5: 0 | L5: 0 | M5: 0 | N5: 0 | O5: 0 | P5: 0 | Q5: 0 | R5: 0 | S5: 0 | T5: 0 | U5: 0 | V5: 0 | W5: 0 | X5: 0 | Y5: 0 | Z5: 0 | AA5: 0 | AB5: 0 | AC5: 0 | AD5: 0 | AE5: 0 | AF5: 0
A6: ships | B6: 0 | C6: 0 | D6: 0 | E6: 0 | F6: 0 | G6: 0 | H6: 0 | I6: 0 | J6: 0 | K6: 0 | L6: 0 | M6: 0 | N6: 0 | O6: 0 | P6: 0 | Q6: 0 | R6: 0 | S6: 0 | T6: 0 | U6: 0 | V6: 0 | W6: 0 | X6: 0 | Y6: 0 | Z6: 0 | AA6: 0 | AB6: 0 | AC6: 0 | AD6: 0 | AE6: 0 | AF6: 0
A7: motorbikes | B7: 0 | C7: 0 | D7: 0 | E7: 0 | F7: 0 | G7: 0 | H7: 0 | I7: 0 | J7: 0 | K7: 0 | L7: 0 | M7: 0 | N7: 0 | O7: 0 | P7: 0 | Q7: 0 | R7: 0 | S7: 0 | T7: 0 | U7: 0 | V7: 0 | W7: 0 | X7: 0 | Y7: 0 | Z7: 0 | AA7: 0 | AB7: 0 | AC7: 0 | AD7: 0 | AE7: 0 | AF7: 0
